2019-09-12 03:16:41,032 INFO: Microblog startup [in C:\Users\dsandhu\Documents\gitkraken\flaskMegaTutorial2\microblog\app\__init__.py:55]
2019-09-12 03:21:31,946 ERROR: Exception on /edit_profile [POST] [in C:\Users\dsandhu\AppData\Local\Continuum\anaconda3\lib\site-packages\flask\app.py:1891]
Traceback (most recent call last):
  File "C:\Users\dsandhu\AppData\Local\Continuum\anaconda3\lib\site-packages\sqlalchemy\engine\base.py", line 1244, in _execute_context
    cursor, statement, parameters, context
  File "C:\Users\dsandhu\AppData\Local\Continuum\anaconda3\lib\site-packages\sqlalchemy\engine\default.py", line 550, in do_execute
    cursor.execute(statement, parameters)
sqlite3.IntegrityError: UNIQUE constraint failed: user.username

The above exception was the direct cause of the following exception:

Traceback (most recent call last):
  File "C:\Users\dsandhu\AppData\Local\Continuum\anaconda3\lib\site-packages\flask\app.py", line 2446, in wsgi_app
    response = self.full_dispatch_request()
  File "C:\Users\dsandhu\AppData\Local\Continuum\anaconda3\lib\site-packages\flask\app.py", line 1951, in full_dispatch_request
    rv = self.handle_user_exception(e)
  File "C:\Users\dsandhu\AppData\Local\Continuum\anaconda3\lib\site-packages\flask\app.py", line 1820, in handle_user_exception
    reraise(exc_type, exc_value, tb)
  File "C:\Users\dsandhu\AppData\Local\Continuum\anaconda3\lib\site-packages\flask\_compat.py", line 39, in reraise
    raise value
  File "C:\Users\dsandhu\AppData\Local\Continuum\anaconda3\lib\site-packages\flask\app.py", line 1949, in full_dispatch_request
    rv = self.dispatch_request()
  File "C:\Users\dsandhu\AppData\Local\Continuum\anaconda3\lib\site-packages\flask\app.py", line 1935, in dispatch_request
    return self.view_functions[rule.endpoint](**req.view_args)
  File "C:\Users\dsandhu\AppData\Local\Continuum\anaconda3\lib\site-packages\flask_login\utils.py", line 261, in decorated_view
    return func(*args, **kwargs)
  File "C:\Users\dsandhu\Documents\gitkraken\flaskMegaTutorial2\microblog\app\routes.py", line 89, in edit_profile
    db.session.commit()
  File "C:\Users\dsandhu\AppData\Local\Continuum\anaconda3\lib\site-packages\sqlalchemy\orm\scoping.py", line 162, in do
    return getattr(self.registry(), name)(*args, **kwargs)
  File "C:\Users\dsandhu\AppData\Local\Continuum\anaconda3\lib\site-packages\sqlalchemy\orm\session.py", line 1027, in commit
    self.transaction.commit()
  File "C:\Users\dsandhu\AppData\Local\Continuum\anaconda3\lib\site-packages\sqlalchemy\orm\session.py", line 494, in commit
    self._prepare_impl()
  File "C:\Users\dsandhu\AppData\Local\Continuum\anaconda3\lib\site-packages\sqlalchemy\orm\session.py", line 473, in _prepare_impl
    self.session.flush()
  File "C:\Users\dsandhu\AppData\Local\Continuum\anaconda3\lib\site-packages\sqlalchemy\orm\session.py", line 2459, in flush
    self._flush(objects)
  File "C:\Users\dsandhu\AppData\Local\Continuum\anaconda3\lib\site-packages\sqlalchemy\orm\session.py", line 2597, in _flush
    transaction.rollback(_capture_exception=True)
  File "C:\Users\dsandhu\AppData\Local\Continuum\anaconda3\lib\site-packages\sqlalchemy\util\langhelpers.py", line 68, in __exit__
    compat.reraise(exc_type, exc_value, exc_tb)
  File "C:\Users\dsandhu\AppData\Local\Continuum\anaconda3\lib\site-packages\sqlalchemy\util\compat.py", line 154, in reraise
    raise value
  File "C:\Users\dsandhu\AppData\Local\Continuum\anaconda3\lib\site-packages\sqlalchemy\orm\session.py", line 2557, in _flush
    flush_context.execute()
  File "C:\Users\dsandhu\AppData\Local\Continuum\anaconda3\lib\site-packages\sqlalchemy\orm\unitofwork.py", line 422, in execute
    rec.execute(self)
  File "C:\Users\dsandhu\AppData\Local\Continuum\anaconda3\lib\site-packages\sqlalchemy\orm\unitofwork.py", line 589, in execute
    uow,
  File "C:\Users\dsandhu\AppData\Local\Continuum\anaconda3\lib\site-packages\sqlalchemy\orm\persistence.py", line 236, in save_obj
    update,
  File "C:\Users\dsandhu\AppData\Local\Continuum\anaconda3\lib\site-packages\sqlalchemy\orm\persistence.py", line 996, in _emit_update_statements
    statement, multiparams
  File "C:\Users\dsandhu\AppData\Local\Continuum\anaconda3\lib\site-packages\sqlalchemy\engine\base.py", line 988, in execute
    return meth(self, multiparams, params)
  File "C:\Users\dsandhu\AppData\Local\Continuum\anaconda3\lib\site-packages\sqlalchemy\sql\elements.py", line 287, in _execute_on_connection
    return connection._execute_clauseelement(self, multiparams, params)
  File "C:\Users\dsandhu\AppData\Local\Continuum\anaconda3\lib\site-packages\sqlalchemy\engine\base.py", line 1107, in _execute_clauseelement
    distilled_params,
  File "C:\Users\dsandhu\AppData\Local\Continuum\anaconda3\lib\site-packages\sqlalchemy\engine\base.py", line 1248, in _execute_context
    e, statement, parameters, cursor, context
  File "C:\Users\dsandhu\AppData\Local\Continuum\anaconda3\lib\site-packages\sqlalchemy\engine\base.py", line 1466, in _handle_dbapi_exception
    util.raise_from_cause(sqlalchemy_exception, exc_info)
  File "C:\Users\dsandhu\AppData\Local\Continuum\anaconda3\lib\site-packages\sqlalchemy\util\compat.py", line 399, in raise_from_cause
    reraise(type(exception), exception, tb=exc_tb, cause=cause)
  File "C:\Users\dsandhu\AppData\Local\Continuum\anaconda3\lib\site-packages\sqlalchemy\util\compat.py", line 153, in reraise
    raise value.with_traceback(tb)
  File "C:\Users\dsandhu\AppData\Local\Continuum\anaconda3\lib\site-packages\sqlalchemy\engine\base.py", line 1244, in _execute_context
    cursor, statement, parameters, context
  File "C:\Users\dsandhu\AppData\Local\Continuum\anaconda3\lib\site-packages\sqlalchemy\engine\default.py", line 550, in do_execute
    cursor.execute(statement, parameters)
sqlalchemy.exc.IntegrityError: (sqlite3.IntegrityError) UNIQUE constraint failed: user.username
[SQL: UPDATE user SET username=?, about_me=? WHERE user.id = ?]
[parameters: ('susan', 'asdf', 3)]
(Background on this error at: http://sqlalche.me/e/gkpj)
2019-09-12 10:38:01,380 INFO: Microblog startup [in C:\Users\dsandhu\Documents\gitkraken\flaskMegaTutorial2\microblog\app\__init__.py:55]
2019-09-12 10:38:45,970 ERROR: Exception on /edit_profile [GET] [in C:\Users\dsandhu\AppData\Local\Continuum\anaconda3\lib\site-packages\flask\app.py:1891]
Traceback (most recent call last):
  File "C:\Users\dsandhu\AppData\Local\Continuum\anaconda3\lib\site-packages\flask\app.py", line 2446, in wsgi_app
    response = self.full_dispatch_request()
  File "C:\Users\dsandhu\AppData\Local\Continuum\anaconda3\lib\site-packages\flask\app.py", line 1951, in full_dispatch_request
    rv = self.handle_user_exception(e)
  File "C:\Users\dsandhu\AppData\Local\Continuum\anaconda3\lib\site-packages\flask\app.py", line 1820, in handle_user_exception
    reraise(exc_type, exc_value, tb)
  File "C:\Users\dsandhu\AppData\Local\Continuum\anaconda3\lib\site-packages\flask\_compat.py", line 39, in reraise
    raise value
  File "C:\Users\dsandhu\AppData\Local\Continuum\anaconda3\lib\site-packages\flask\app.py", line 1949, in full_dispatch_request
    rv = self.dispatch_request()
  File "C:\Users\dsandhu\AppData\Local\Continuum\anaconda3\lib\site-packages\flask\app.py", line 1935, in dispatch_request
    return self.view_functions[rule.endpoint](**req.view_args)
  File "C:\Users\dsandhu\AppData\Local\Continuum\anaconda3\lib\site-packages\flask_login\utils.py", line 261, in decorated_view
    return func(*args, **kwargs)
  File "C:\Users\dsandhu\Documents\gitkraken\flaskMegaTutorial2\microblog\app\routes.py", line 85, in edit_profile
    form = EditProfileForm(current_user.username)
  File "C:\Users\dsandhu\AppData\Local\Continuum\anaconda3\lib\site-packages\wtforms\form.py", line 212, in __call__
    return type.__call__(cls, *args, **kwargs)
  File "C:\Users\dsandhu\Documents\gitkraken\flaskMegaTutorial2\microblog\app\forms.py", line 38, in __init__
    super(EditProfileForm, self)._init__(*args, **kwargs)
AttributeError: 'super' object has no attribute '_init__'
2019-09-12 10:38:54,407 ERROR: Exception on /edit_profile [GET] [in C:\Users\dsandhu\AppData\Local\Continuum\anaconda3\lib\site-packages\flask\app.py:1891]
Traceback (most recent call last):
  File "C:\Users\dsandhu\AppData\Local\Continuum\anaconda3\lib\site-packages\flask\app.py", line 2446, in wsgi_app
    response = self.full_dispatch_request()
  File "C:\Users\dsandhu\AppData\Local\Continuum\anaconda3\lib\site-packages\flask\app.py", line 1951, in full_dispatch_request
    rv = self.handle_user_exception(e)
  File "C:\Users\dsandhu\AppData\Local\Continuum\anaconda3\lib\site-packages\flask\app.py", line 1820, in handle_user_exception
    reraise(exc_type, exc_value, tb)
  File "C:\Users\dsandhu\AppData\Local\Continuum\anaconda3\lib\site-packages\flask\_compat.py", line 39, in reraise
    raise value
  File "C:\Users\dsandhu\AppData\Local\Continuum\anaconda3\lib\site-packages\flask\app.py", line 1949, in full_dispatch_request
    rv = self.dispatch_request()
  File "C:\Users\dsandhu\AppData\Local\Continuum\anaconda3\lib\site-packages\flask\app.py", line 1935, in dispatch_request
    return self.view_functions[rule.endpoint](**req.view_args)
  File "C:\Users\dsandhu\AppData\Local\Continuum\anaconda3\lib\site-packages\flask_login\utils.py", line 261, in decorated_view
    return func(*args, **kwargs)
  File "C:\Users\dsandhu\Documents\gitkraken\flaskMegaTutorial2\microblog\app\routes.py", line 85, in edit_profile
    form = EditProfileForm(current_user.username)
  File "C:\Users\dsandhu\AppData\Local\Continuum\anaconda3\lib\site-packages\wtforms\form.py", line 212, in __call__
    return type.__call__(cls, *args, **kwargs)
  File "C:\Users\dsandhu\Documents\gitkraken\flaskMegaTutorial2\microblog\app\forms.py", line 38, in __init__
    super(EditProfileForm, self)._init__(*args, **kwargs)
AttributeError: 'super' object has no attribute '_init__'
2019-09-12 10:39:45,313 INFO: Microblog startup [in C:\Users\dsandhu\Documents\gitkraken\flaskMegaTutorial2\microblog\app\__init__.py:55]
