2019-10-10 18:16:06,807 ERROR: Exception on /reset_password_request [POST] [in C:\Users\dsandhu\AppData\Local\Continuum\anaconda3\lib\site-packages\flask\app.py:1891]
Traceback (most recent call last):
  File "C:\Users\dsandhu\AppData\Local\Continuum\anaconda3\lib\site-packages\flask\app.py", line 2446, in wsgi_app
    response = self.full_dispatch_request()
  File "C:\Users\dsandhu\AppData\Local\Continuum\anaconda3\lib\site-packages\flask\app.py", line 1951, in full_dispatch_request
    rv = self.handle_user_exception(e)
  File "C:\Users\dsandhu\AppData\Local\Continuum\anaconda3\lib\site-packages\flask\app.py", line 1820, in handle_user_exception
    reraise(exc_type, exc_value, tb)
  File "C:\Users\dsandhu\AppData\Local\Continuum\anaconda3\lib\site-packages\flask\_compat.py", line 39, in reraise
    raise value
  File "C:\Users\dsandhu\AppData\Local\Continuum\anaconda3\lib\site-packages\flask\app.py", line 1949, in full_dispatch_request
    rv = self.dispatch_request()
  File "C:\Users\dsandhu\AppData\Local\Continuum\anaconda3\lib\site-packages\flask\app.py", line 1935, in dispatch_request
    return self.view_functions[rule.endpoint](**req.view_args)
  File "C:\Users\dsandhu\Documents\gitkraken\flaskMegaTutorial2\microblog\app\routes.py", line 144, in reset_password_request
    send_password_reset_email(user)
  File "C:\Users\dsandhu\Documents\gitkraken\flaskMegaTutorial2\microblog\app\email.py", line 19, in send_password_reset_email
    html_body=render_template('email/reset_password.html', user=user, token=token)
  File "C:\Users\dsandhu\Documents\gitkraken\flaskMegaTutorial2\microblog\app\email.py", line 9, in send_email
    mail.send(msg)
  File "C:\Users\dsandhu\AppData\Local\Continuum\anaconda3\lib\site-packages\flask_mail.py", line 491, in send
    with self.connect() as connection:
  File "C:\Users\dsandhu\AppData\Local\Continuum\anaconda3\lib\site-packages\flask_mail.py", line 144, in __enter__
    self.host = self.configure_host()
  File "C:\Users\dsandhu\AppData\Local\Continuum\anaconda3\lib\site-packages\flask_mail.py", line 158, in configure_host
    host = smtplib.SMTP(self.mail.server, self.mail.port)
  File "C:\Users\dsandhu\AppData\Local\Continuum\anaconda3\lib\smtplib.py", line 251, in __init__
    (code, msg) = self.connect(host, port)
  File "C:\Users\dsandhu\AppData\Local\Continuum\anaconda3\lib\smtplib.py", line 336, in connect
    self.sock = self._get_socket(host, port, self.timeout)
  File "C:\Users\dsandhu\AppData\Local\Continuum\anaconda3\lib\smtplib.py", line 307, in _get_socket
    self.source_address)
  File "C:\Users\dsandhu\AppData\Local\Continuum\anaconda3\lib\socket.py", line 727, in create_connection
    raise err
  File "C:\Users\dsandhu\AppData\Local\Continuum\anaconda3\lib\socket.py", line 716, in create_connection
    sock.connect(sa)
TimeoutError: [WinError 10060] A connection attempt failed because the connected party did not properly respond after a period of time, or established connection failed because connected host has failed to respond
